Workbook

Sheet 기업정보
A1: 시연용 가상 데이터. 실제 기업 자료가 아님
A3: template_version | B3: 0.3
A4: company | B4: 한빛반도체
A5: company_en | B5: Hanbit Semiconductor
A6: data_class | B6: 가상데이터
A7: 기준기간 | B7: 2023-01 ~ 2025-12 (월별, 36개월)
A8: 금액 통화 | B8: USD (결제통화)
A9: 환산 환율 | B9: FRED H.10 EXKOUS 원/달러 월평균 (junhee/data/raw/external/fred_EXKOUS_krw_per_usd_monthly.csv)
A10: 생성 근거 | B10: 삼성전자 DS부문 사업보고서 3개년(2023~2025) 연간 규모·지역·제품 비율을 1/500로 축소. 월별 흐름·거래처·단가는 가정 (근거 시트)
A11: 작성일 | B11: 2026-09-26
A13: 대시보드 항목 ↔ 이 파일의 입력값
A14: 대시보드 항목 | B14: 이 파일에서 쓰는 값 | C14: 공개자료·API 쪽에서 붙는 값 (이 파일에는 없음)
A15: 공통 | B15: 회사·제품명(제품정보), 입력 HSK와 분석 HS6(제품정보), 목적국(수출실적·거래처), 자료기간(기준기간) | C15: 기준일·출처는 공개자료 쪽
A16: 1. 규제 | B16: 제품정보.입력HSK → HSK 연계표 통제번호 후보 / 거래처.법인명·주소 → CSL 검색 | C16: 통제번호·품목명, 목적국 수입규제 기록, CSL 명단 (발견 사실만 표시, '없음'을 '규제 없음'으로 판정하지 않음)
A17: 2. 시장성 | B17: 수출실적의 목적국·HS·월별 금액(회사 수출 흐름, 월별집계 시트) | C17: 목적국 총수입, 한국의 해당국 수출, 성장률, 한국산 점유율, WSTS 업황
A18: 3. 가격 | B18: 수출실적의 금액·순중량(kg) → 회사 kg당 단가 / 통화 → 참고환율 통화 선택 | C18: 무역통계 단가, 관세 참고치(WTO), 참고환율, 수출입물가지수, 운송비 참고
A19: 4. 물류 | B19: 물류 시트의 출발지·도착지 코드(공항 IATA·항만 UN/LOCODE)와 선적일 → 운항·입출항 조회 조건 / 예정·실제 도착일 → 납기 준수율·리드타임 / 운임(USD) → 운송비 비중 (v0.3 추가, 가정값) | C19: 인천공항 화물편 일정·운항 횟수, 선박 입출항 기록 (직항·배송시간은 확정하지 않음)
A20: 5. 안정성 | B20: 월별집계 시트의 월별 금액·전월대비(회사 수출 변동 참고) | C20: 목적국 월별 수입금액, CV, 급감 이력, 환율 변동성
A21: 제외 | B21: 원가·이익률, 허가·인증 충족 여부 — 이 파일에 넣지 않음 (납기·운임은 시연용 가정값으로 물류 시트에 추가) | C21: 팀 공유 문서 '이번 기본 범위에서 제외할 항목'
A23: 실제 수치는 '근거' 시트 A에 출처와 함께 있고, 이 파일의 개별 거래·거래처·단가는 모두 가상입니다.
A24: 화면·발표에서는 가상 회사명만 쓰고 실제 기업명과 점수를 연결해 표시하지 않습니다.

Sheet 제품정보
A1: 제품ID | B1: 모델명 | C1: 제품군 | D1: 입력HSK | E1: HS코드 | F1: HS버전 | G1: 제조국 | H1: 사양 | I1: 단위 | J1: 단위중량(g) | K1: 분류비고
A2: P-HB-001 | B2: HBD5-16G | C2: DRAM | D2: 8542321010 | E2: 854232 | F2: HS2022 | G2: 대한민국 | H2: DDR5 16Gb 6400Mbps | I2: EA | J2: 0.45
A3: P-HB-002 | B3: HBL-HBM3E | C3: DRAM(HBM) | D3: 8542323000 | E3: 854232 | F3: HS2022 | G3: 대한민국 | H3: HBM3E 12단 36GB | I3: EA | J3: 2.2 | K3: 적층 메모리(복합구조칩)로 가정 — 품목분류 확인 필요
A4: P-HB-003 | B4: HBN-1T | C4: NAND | D4: 8542321030 | E4: 854232 | F4: HS2022 | G4: 대한민국 | H4: TLC 1Tb V-NAND | I4: EA | J4: 0.65
A5: P-HB-004 | B5: HBA-M9 | C5: 시스템반도체(모바일AP) | D5: 8542311000 | E5: 854231 | F5: HS2022 | G5: 대한민국 | H5: 모바일 AP 4nm | I5: EA | J5: 1.1 | K5: 비메모리(System LSI·Foundry) 대표 품목

Sheet 거래처
A1: 거래처ID | B1: 법인명 | C1: 별칭 | D1: 주소 | E1: 도시 | F1: 국가 | G1: 국가코드 | H1: 최종사용자관계
A2: C-HB-01 | B2: North River Systems Inc. | C2: 노스리버 시스템즈 | D2: 1200 Harbor Blvd, San Jose, CA 95112 | E2: San Jose | F2: 미국 | G2: US | H2: 최종사용자
A3: C-HB-02 | B3: Pacific Crest Cloud LLC | C3: 퍼시픽크레스트 클라우드 | D3: 88 Terminal Ave, Seattle, WA 98134 | E3: Seattle | F3: 미국 | G3: US | H3: 최종사용자
A4: C-HB-03 | B4: Tijuana Assembly S.A. de C.V. | C4: 티후아나 어셈블리 | D4: Blvd. Industrial 900, Tijuana, B.C. | E4: Tijuana | F4: 멕시코 | G4: MX | H4: 최종사용자
A5: C-HB-04 | B5: Maple Server Corp. | C5: 메이플 서버 | D5: 200 Bay St, Toronto, ON | E5: Toronto | F5: 캐나다 | G5: CA | H5: 최종사용자
A6: C-HB-05 | B6: Rheinland Compute GmbH | C6: 라인란트 컴퓨트 | D6: Königsallee 60, Düsseldorf | E6: Düsseldorf | F6: 독일 | G6: DE | H6: 유통업체
A7: C-HB-06 | B7: Song Hong Electronics Co., Ltd. | C7: 송홍 일렉트로닉스 | D7: Yen Phong IP, Bac Ninh | E7: Bac Ninh | F7: 베트남 | G7: VN | H7: 최종사용자
A8: C-HB-07 | B8: Delhi Digital Pvt. Ltd. | C8: 델리 디지털 | D8: Sector 62, Noida, Uttar Pradesh | E8: Noida | F8: 인도 | G8: IN | H8: 최종사용자
A9: C-HB-08 | B9: Huarun Storage Co., Ltd. | C9: 화룬 스토리지 | D9: 88 Keyuan Rd, Nanshan, Shenzhen | E9: Shenzhen | F9: 중국 | G9: CN | H9: 최종사용자
A10: C-HB-09 | B10: Jiangbei Mobile Devices Co., Ltd. | C10: 장베이 모바일 | D10: Liangjiang New Area, Chongqing | E10: Chongqing | F10: 중국 | G10: CN | H10: 최종사용자

Sheet 수출실적
A1: 실적ID | B1: 거래일 | C1: 거래월 | D1: 연도 | E1: 제품ID | F1: 거래처ID | G1: 목적국 | H1: 목적국코드 | I1: 수량 | J1: 단위 | K1: 순중량(kg) | L1: 금액 | M1: 통화 | N1: 인코텀즈 | O1: 취소반품 | P1: 적용환율(KRW/USD) | Q1: 원화환산(원)
A2: R-HB-0001 | B2: 44929 | C2: 2023-01 | D2: 2023 | E2: P-HB-001 | F2: C-HB-06 | G2: 베트남 | H2: VN | I2: 97688 | J2: EA | K2: 43.96 | L2: 419733.96 | M2: USD | N2: FOB | O2: N | P2: 1243.0705 | Q2: =IF(OR(L2="",M2="",P2=""),"",L2*P2)
A3: R-HB-0002 | B3: 44929 | C3: 2023-01 | D3: 2023 | E3: P-HB-002 | F3: C-HB-09 | G3: 중국 | H3: CN | I3: 161 | J3: EA | K3: 0.35 | L3: 47298.54 | M3: USD | N3: FOB | O3: N | P3: 1243.0705 | Q3: =IF(OR(L3="",M3="",P3=""),"",L3*P3)
A4: R-HB-0003 | B4: 44931 | C4: 2023-01 | D4: 2023 | E4: P-HB-002 | F4: C-HB-05 | G4: 독일 | H4: DE | I4: 203 | J4: EA | K4: 0.45 | L4: 60952.47 | M4: USD | N4: FOB | O4: N | P4: 1243.0705 | Q4: =IF(OR(L4="",M4="",P4=""),"",L4*P4)
A5: R-HB-0004 | B5: 44931 | C5: 2023-01 | D5: 2023 | E5: P-HB-004 | F5: C-HB-08 | G5: 중국 | H5: CN | I5: 16900 | J5: EA | K5: 18.59 | L5: 454927.24 | M5: USD | N5: FOB | O5: N | P5: 1243.0705 | Q5: =IF(OR(L5="",M5="",P5=""),"",L5*P5)
A6: R-HB-0005 | B6: 44932 | C6: 2023-01 | D6: 2023 | E6: P-HB-002 | F6: C-HB-06 | G6: 베트남 | H6: VN | I6: 179 | J6: EA | K6: 0.39 | L6: 51186.56 | M6: USD | N6: FOB | O6: N | P6: 1243.0705 | Q6: =IF(OR(L6="",M6="",P6=""),"",L6*P6)
A7: R-HB-0006 | B7: 44933 | C7: 2023-01 | D7: 2023 | E7: P-HB-003 | F7: C-HB-01 | G7: 미국 | H7: US | I7: 60248 | J7: EA | K7: 39.16 | L7: 356127.21 | M7: USD | N7: FOB | O7: N | P7: 1243.0705 | Q7: =IF(OR(L7="",M7="",P7=""),"",L7*P7)
A8: R-HB-0007 | B8: 44933 | C8: 2023-01 | D8: 2023 | E8: P-HB-003 | F8: C-HB-05 | G8: 독일 | H8: DE | I8: 47810 | J8: EA | K8: 31.08 | L8: 274490.99 | M8: USD | N8: FOB | O8: N | P8: 1243.0705 | Q8: =IF(OR(L8="",M8="",P8=""),"",L8*P8)
A9: R-HB-0008 | B9: 44933 | C9: 2023-01 | D9: 2023 | E9: P-HB-002 | F9: C-HB-07 | G9: 인도 | H9: IN | I9: 120 | J9: EA | K9: 0.26 | L9: 33714.46 | M9: USD | N9: FOB | O9: N | P9: 1243.0705 | Q9: =IF(OR(L9="",M9="",P9=""),"",L9*P9)
A10: R-HB-0009 | B10: 44934 | C10: 2023-01 | D10: 2023 | E10: P-HB-001 | F10: C-HB-08 | G10: 중국 | H10: CN | I10: 143680 | J10: EA | K10: 64.66 | L10: 602894.97 | M10: USD | N10: FOB | O10: N | P10: 1243.0705 | Q10: =IF(OR(L10="",M10="",P10=""),"",L10*P10)
A11: R-HB-0010 | B11: 44935 | C11: 2023-01 | D11: 2023 | E11: P-HB-003 | F11: C-HB-09 | G11: 중국 | H11: CN | I11: 31705 | J11: EA | K11: 20.61 | L11: 189381.83 | M11: USD | N11: FOB | O11: N | P11: 1243.0705 | Q11: =IF(OR(L11="",M11="",P11=""),"",L11*P11)
A12: R-HB-0011 | B12: 44936 | C12: 2023-01 | D12: 2023 | E12: P-HB-002 | F12: C-HB-04 | G12: 캐나다 | H12: CA | I12: 24 | J12: EA | K12: 0.05 | L12: 7012.08 | M12: USD | N12: FOB | O12: N | P12: 1243.0705 | Q12: =IF(OR(L12="",M12="",P12=""),"",L12*P12)
A13: R-HB-0012 | B13: 44937 | C13: 2023-01 | D13: 2023 | E13: P-HB-002 | F13: C-HB-01 | G13: 미국 | H13: US | I13: 271 | J13: EA | K13: 0.6 | L13: 75702.86 | M13: USD | N13: FOB | O13: N | P13: 1243.0705 | Q13: =IF(OR(L13="",M13="",P13=""),"",L13*P13)
... A1297: R-HB-1296 | B1297: 46018 | C1297: 2025-12 | D1297: 2025 | E1297: P-HB-003 | F1297: C-HB-06 | G1297: 베트남 | H1297: VN | I1297: 36095 | J1297: EA | K1297: 23.46 | L1297: 319636 | M1297: USD | N1297: FOB | O1297: N | P1297: 1465.355 | Q1297: =IF(OR(L1297="",M1297="",P1297=""),"",L1297*P1297)

Sheet 물류
A1: 물류ID | B1: 실적ID | C1: 운송수단 | D1: 출발지 | E1: 출발지코드 | F1: 도착지 | G1: 도착지코드 | H1: 선적일 | I1: 예정도착일 | J1: 실제도착일 | K1: 운임(USD)
A2: L-HB-0001 | B2: R-HB-0001 | C2: 항공 | D2: 인천공항 | E2: ICN | F2: 하노이공항 | G2: HAN | H2: 44929 | I2: 44932 | J2: 44932 | K2: 214.46
A3: L-HB-0002 | B3: R-HB-0002 | C3: 항공 | D3: 인천공항 | E3: ICN | F3: 충칭공항 | G3: CKG | H3: 44929 | I3: 44932 | J3: 44932 | K3: 135
A4: L-HB-0003 | B4: R-HB-0003 | C4: 항공 | D4: 인천공항 | E4: ICN | F4: 프랑크푸르트공항 | G4: FRA | H4: 44931 | I4: 44934 | J4: 44934 | K4: 135
A5: L-HB-0004 | B5: R-HB-0004 | C5: 항공 | D5: 인천공항 | E5: ICN | F5: 선전공항 | G5: SZX | H5: 44931 | I5: 44933 | J5: 44933 | K5: 135
A6: L-HB-0005 | B6: R-HB-0005 | C6: 항공 | D6: 인천공항 | E6: ICN | F6: 하노이공항 | G6: HAN | H6: 44932 | I6: 44933 | J6: 44933 | K6: 135
A7: L-HB-0006 | B7: R-HB-0006 | C7: 항공 | D7: 인천공항 | E7: ICN | F7: 로스앤젤레스공항 | G7: LAX | H7: 44933 | I7: 44935 | J7: 44935 | K7: 275.71
A8: L-HB-0007 | B8: R-HB-0007 | C8: 항공 | D8: 인천공항 | E8: ICN | F8: 프랑크푸르트공항 | G8: FRA | H8: 44933 | I8: 44936 | J8: 44936 | K8: 237.83
A9: L-HB-0008 | B9: R-HB-0008 | C9: 항공 | D9: 인천공항 | E9: ICN | F9: 델리공항 | G9: DEL | H9: 44933 | I9: 44935 | J9: 44935 | K9: 135
A10: L-HB-0009 | B10: R-HB-0009 | C10: 항공 | D10: 인천공항 | E10: ICN | F10: 선전공항 | G10: SZX | H10: 44934 | I10: 44937 | J10: 44937 | K10: 294.15
A11: L-HB-0010 | B11: R-HB-0010 | C11: 해상 | D11: 부산항 | E11: KRPUS | F11: 상하이항 | G11: CNSHA | H11: 44935 | I11: 44939 | J11: 44939 | K11: 530
A12: L-HB-0011 | B12: R-HB-0011 | C12: 항공 | D12: 인천공항 | E12: ICN | F12: 토론토공항 | G12: YYZ | H12: 44936 | I12: 44941 | J12: 44941 | K12: 135
A13: L-HB-0012 | B13: R-HB-0012 | C13: 항공 | D13: 인천공항 | E13: ICN | F13: 로스앤젤레스공항 | G13: LAX | H13: 44937 | I13: 44939 | J13: 44938 | K13: 135
... A1297: L-HB-1296 | B1297: R-HB-1296 | C1297: 해상 | D1297: 부산항 | E1297: KRPUS | F1297: 하이퐁항 | G1297: VNHPH | H1297: 46018 | I1297: 46026 | J1297: 46026 | K1297: 530

Sheet 월별집계
A1: 거래월 | B1: 미국 (USD) | C1: 멕시코 (USD) | D1: 캐나다 (USD) | E1: 독일 (USD) | F1: 베트남 (USD) | G1: 인도 (USD) | H1: 중국 (USD) | I1: 합계 (USD) | J1: 전월대비 | K1: 금액 빈칸 행수
A2: 2023-01 | B2: =SUMIFS(수출실적!$L$2:$L$1297,수출실적!$C$2:$C$1297,$A2,수출실적!$G$2:$G$1297,"미국") | C2: =SUMIFS(수출실적!$L$2:$L$1297,수출실적!$C$2:$C$1297,$A2,수출실적!$G$2:$G$1297,"멕시코") | D2: =SUMIFS(수출실적!$L$2:$L$1297,수출실적!$C$2:$C$1297,$A2,수출실적!$G$2:$G$1297,"캐나다") | E2: =SUMIFS(수출실적!$L$2:$L$1297,수출실적!$C$2:$C$1297,$A2,수출실적!$G$2:$G$1297,"독일") | F2: =SUMIFS(수출실적!$L$2:$L$1297,수출실적!$C$2:$C$1297,$A2,수출실적!$G$2:$G$1297,"베트남") | G2: =SUMIFS(수출실적!$L$2:$L$1297,수출실적!$C$2:$C$1297,$A2,수출실적!$G$2:$G$1297,"인도") | H2: =SUMIFS(수출실적!$L$2:$L$1297,수출실적!$C$2:$C$1297,$A2,수출실적!$G$2:$G$1297,"중국") | I2: =SUM(B2:H2) | K2: =SUMPRODUCT((수출실적!$C$2:$C$1297=$A2)*(수출실적!$L$2:$L$1297=""))
A3: 2023-02 | B3: =SUMIFS(수출실적!$L$2:$L$1297,수출실적!$C$2:$C$1297,$A3,수출실적!$G$2:$G$1297,"미국") | C3: =SUMIFS(수출실적!$L$2:$L$1297,수출실적!$C$2:$C$1297,$A3,수출실적!$G$2:$G$1297,"멕시코") | D3: =SUMIFS(수출실적!$L$2:$L$1297,수출실적!$C$2:$C$1297,$A3,수출실적!$G$2:$G$1297,"캐나다") | E3: =SUMIFS(수출실적!$L$2:$L$1297,수출실적!$C$2:$C$1297,$A3,수출실적!$G$2:$G$1297,"독일") | F3: =SUMIFS(수출실적!$L$2:$L$1297,수출실적!$C$2:$C$1297,$A3,수출실적!$G$2:$G$1297,"베트남") | G3: =SUMIFS(수출실적!$L$2:$L$1297,수출실적!$C$2:$C$1297,$A3,수출실적!$G$2:$G$1297,"인도") | H3: =SUMIFS(수출실적!$L$2:$L$1297,수출실적!$C$2:$C$1297,$A3,수출실적!$G$2:$G$1297,"중국") | I3: =SUM(B3:H3) | J3: =IF(I2=0,"",I3/I2-1) | K3: =SUMPRODUCT((수출실적!$C$2:$C$1297=$A3)*(수출실적!$L$2:$L$1297=""))
A4: 2023-03 | B4: =SUMIFS(수출실적!$L$2:$L$1297,수출실적!$C$2:$C$1297,$A4,수출실적!$G$2:$G$1297,"미국") | C4: =SUMIFS(수출실적!$L$2:$L$1297,수출실적!$C$2:$C$1297,$A4,수출실적!$G$2:$G$1297,"멕시코") | D4: =SUMIFS(수출실적!$L$2:$L$1297,수출실적!$C$2:$C$1297,$A4,수출실적!$G$2:$G$1297,"캐나다") | E4: =SUMIFS(수출실적!$L$2:$L$1297,수출실적!$C$2:$C$1297,$A4,수출실적!$G$2:$G$1297,"독일") | F4: =SUMIFS(수출실적!$L$2:$L$1297,수출실적!$C$2:$C$1297,$A4,수출실적!$G$2:$G$1297,"베트남") | G4: =SUMIFS(수출실적!$L$2:$L$1297,수출실적!$C$2:$C$1297,$A4,수출실적!$G$2:$G$1297,"인도") | H4: =SUMIFS(수출실적!$L$2:$L$1297,수출실적!$C$2:$C$1297,$A4,수출실적!$G$2:$G$1297,"중국") | I4: =SUM(B4:H4) | J4: =IF(I3=0,"",I4/I3-1) | K4: =SUMPRODUCT((수출실적!$C$2:$C$1297=$A4)*(수출실적!$L$2:$L$1297=""))
A5: 2023-04 | B5: =SUMIFS(수출실적!$L$2:$L$1297,수출실적!$C$2:$C$1297,$A5,수출실적!$G$2:$G$1297,"미국") | C5: =SUMIFS(수출실적!$L$2:$L$1297,수출실적!$C$2:$C$1297,$A5,수출실적!$G$2:$G$1297,"멕시코") | D5: =SUMIFS(수출실적!$L$2:$L$1297,수출실적!$C$2:$C$1297,$A5,수출실적!$G$2:$G$1297,"캐나다") | E5: =SUMIFS(수출실적!$L$2:$L$1297,수출실적!$C$2:$C$1297,$A5,수출실적!$G$2:$G$1297,"독일") | F5: =SUMIFS(수출실적!$L$2:$L$1297,수출실적!$C$2:$C$1297,$A5,수출실적!$G$2:$G$1297,"베트남") | G5: =SUMIFS(수출실적!$L$2:$L$1297,수출실적!$C$2:$C$1297,$A5,수출실적!$G$2:$G$1297,"인도") | H5: =SUMIFS(수출실적!$L$2:$L$1297,수출실적!$C$2:$C$1297,$A5,수출실적!$G$2:$G$1297,"중국") | I5: =SUM(B5:H5) | J5: =IF(I4=0,"",I5/I4-1) | K5: =SUMPRODUCT((수출실적!$C$2:$C$1297=$A5)*(수출실적!$L$2:$L$1297=""))
A6: 2023-05 | B6: =SUMIFS(수출실적!$L$2:$L$1297,수출실적!$C$2:$C$1297,$A6,수출실적!$G$2:$G$1297,"미국") | C6: =SUMIFS(수출실적!$L$2:$L$1297,수출실적!$C$2:$C$1297,$A6,수출실적!$G$2:$G$1297,"멕시코") | D6: =SUMIFS(수출실적!$L$2:$L$1297,수출실적!$C$2:$C$1297,$A6,수출실적!$G$2:$G$1297,"캐나다") | E6: =SUMIFS(수출실적!$L$2:$L$1297,수출실적!$C$2:$C$1297,$A6,수출실적!$G$2:$G$1297,"독일") | F6: =SUMIFS(수출실적!$L$2:$L$1297,수출실적!$C$2:$C$1297,$A6,수출실적!$G$2:$G$1297,"베트남") | G6: =SUMIFS(수출실적!$L$2:$L$1297,수출실적!$C$2:$C$1297,$A6,수출실적!$G$2:$G$1297,"인도") | H6: =SUMIFS(수출실적!$L$2:$L$1297,수출실적!$C$2:$C$1297,$A6,수출실적!$G$2:$G$1297,"중국") | I6: =SUM(B6:H6) | J6: =IF(I5=0,"",I6/I5-1) | K6: =SUMPRODUCT((수출실적!$C$2:$C$1297=$A6)*(수출실적!$L$2:$L$1297=""))
A7: 2023-06 | B7: =SUMIFS(수출실적!$L$2:$L$1297,수출실적!$C$2:$C$1297,$A7,수출실적!$G$2:$G$1297,"미국") | C7: =SUMIFS(수출실적!$L$2:$L$1297,수출실적!$C$2:$C$1297,$A7,수출실적!$G$2:$G$1297,"멕시코") | D7: =SUMIFS(수출실적!$L$2:$L$1297,수출실적!$C$2:$C$1297,$A7,수출실적!$G$2:$G$1297,"캐나다") | E7: =SUMIFS(수출실적!$L$2:$L$1297,수출실적!$C$2:$C$1297,$A7,수출실적!$G$2:$G$1297,"독일") | F7: =SUMIFS(수출실적!$L$2:$L$1297,수출실적!$C$2:$C$1297,$A7,수출실적!$G$2:$G$1297,"베트남") | G7: =SUMIFS(수출실적!$L$2:$L$1297,수출실적!$C$2:$C$1297,$A7,수출실적!$G$2:$G$1297,"인도") | H7: =SUMIFS(수출실적!$L$2:$L$1297,수출실적!$C$2:$C$1297,$A7,수출실적!$G$2:$G$1297,"중국") | I7: =SUM(B7:H7) | J7: =IF(I6=0,"",I7/I6-1) | K7: =SUMPRODUCT((수출실적!$C$2:$C$1297=$A7)*(수출실적!$L$2:$L$1297=""))
A8: 2023-07 | B8: =SUMIFS(수출실적!$L$2:$L$1297,수출실적!$C$2:$C$1297,$A8,수출실적!$G$2:$G$1297,"미국") | C8: =SUMIFS(수출실적!$L$2:$L$1297,수출실적!$C$2:$C$1297,$A8,수출실적!$G$2:$G$1297,"멕시코") | D8: =SUMIFS(수출실적!$L$2:$L$1297,수출실적!$C$2:$C$1297,$A8,수출실적!$G$2:$G$1297,"캐나다") | E8: =SUMIFS(수출실적!$L$2:$L$1297,수출실적!$C$2:$C$1297,$A8,수출실적!$G$2:$G$1297,"독일") | F8: =SUMIFS(수출실적!$L$2:$L$1297,수출실적!$C$2:$C$1297,$A8,수출실적!$G$2:$G$1297,"베트남") | G8: =SUMIFS(수출실적!$L$2:$L$1297,수출실적!$C$2:$C$1297,$A8,수출실적!$G$2:$G$1297,"인도") | H8: =SUMIFS(수출실적!$L$2:$L$1297,수출실적!$C$2:$C$1297,$A8,수출실적!$G$2:$G$1297,"중국") | I8: =SUM(B8:H8) | J8: =IF(I7=0,"",I8/I7-1) | K8: =SUMPRODUCT((수출실적!$C$2:$C$1297=$A8)*(수출실적!$L$2:$L$1297=""))
A9: 2023-08 | B9: =SUMIFS(수출실적!$L$2:$L$1297,수출실적!$C$2:$C$1297,$A9,수출실적!$G$2:$G$1297,"미국") | C9: =SUMIFS(수출실적!$L$2:$L$1297,수출실적!$C$2:$C$1297,$A9,수출실적!$G$2:$G$1297,"멕시코") | D9: =SUMIFS(수출실적!$L$2:$L$1297,수출실적!$C$2:$C$1297,$A9,수출실적!$G$2:$G$1297,"캐나다") | E9: =SUMIFS(수출실적!$L$2:$L$1297,수출실적!$C$2:$C$1297,$A9,수출실적!$G$2:$G$1297,"독일") | F9: =SUMIFS(수출실적!$L$2:$L$1297,수출실적!$C$2:$C$1297,$A9,수출실적!$G$2:$G$1297,"베트남") | G9: =SUMIFS(수출실적!$L$2:$L$1297,수출실적!$C$2:$C$1297,$A9,수출실적!$G$2:$G$1297,"인도") | H9: =SUMIFS(수출실적!$L$2:$L$1297,수출실적!$C$2:$C$1297,$A9,수출실적!$G$2:$G$1297,"중국") | I9: =SUM(B9:H9) | J9: =IF(I8=0,"",I9/I8-1) | K9: =SUMPRODUCT((수출실적!$C$2:$C$1297=$A9)*(수출실적!$L$2:$L$1297=""))
A10: 2023-09 | B10: =SUMIFS(수출실적!$L$2:$L$1297,수출실적!$C$2:$C$1297,$A10,수출실적!$G$2:$G$1297,"미국") | C10: =SUMIFS(수출실적!$L$2:$L$1297,수출실적!$C$2:$C$1297,$A10,수출실적!$G$2:$G$1297,"멕시코") | D10: =SUMIFS(수출실적!$L$2:$L$1297,수출실적!$C$2:$C$1297,$A10,수출실적!$G$2:$G$1297,"캐나다") | E10: =SUMIFS(수출실적!$L$2:$L$1297,수출실적!$C$2:$C$1297,$A10,수출실적!$G$2:$G$1297,"독일") | F10: =SUMIFS(수출실적!$L$2:$L$1297,수출실적!$C$2:$C$1297,$A10,수출실적!$G$2:$G$1297,"베트남") | G10: =SUMIFS(수출실적!$L$2:$L$1297,수출실적!$C$2:$C$1297,$A10,수출실적!$G$2:$G$1297,"인도") | H10: =SUMIFS(수출실적!$L$2:$L$1297,수출실적!$C$2:$C$1297,$A10,수출실적!$G$2:$G$1297,"중국") | I10: =SUM(B10:H10) | J10: =IF(I9=0,"",I10/I9-1) | K10: =SUMPRODUCT((수출실적!$C$2:$C$1297=$A10)*(수출실적!$L$2:$L$1297=""))
A11: 2023-10 | B11: =SUMIFS(수출실적!$L$2:$L$1297,수출실적!$C$2:$C$1297,$A11,수출실적!$G$2:$G$1297,"미국") | C11: =SUMIFS(수출실적!$L$2:$L$1297,수출실적!$C$2:$C$1297,$A11,수출실적!$G$2:$G$1297,"멕시코") | D11: =SUMIFS(수출실적!$L$2:$L$1297,수출실적!$C$2:$C$1297,$A11,수출실적!$G$2:$G$1297,"캐나다") | E11: =SUMIFS(수출실적!$L$2:$L$1297,수출실적!$C$2:$C$1297,$A11,수출실적!$G$2:$G$1297,"독일") | F11: =SUMIFS(수출실적!$L$2:$L$1297,수출실적!$C$2:$C$1297,$A11,수출실적!$G$2:$G$1297,"베트남") | G11: =SUMIFS(수출실적!$L$2:$L$1297,수출실적!$C$2:$C$1297,$A11,수출실적!$G$2:$G$1297,"인도") | H11: =SUMIFS(수출실적!$L$2:$L$1297,수출실적!$C$2:$C$1297,$A11,수출실적!$G$2:$G$1297,"중국") | I11: =SUM(B11:H11) | J11: =IF(I10=0,"",I11/I10-1) | K11: =SUMPRODUCT((수출실적!$C$2:$C$1297=$A11)*(수출실적!$L$2:$L$1297=""))
A12: 2023-11 | B12: =SUMIFS(수출실적!$L$2:$L$1297,수출실적!$C$2:$C$1297,$A12,수출실적!$G$2:$G$1297,"미국") | C12: =SUMIFS(수출실적!$L$2:$L$1297,수출실적!$C$2:$C$1297,$A12,수출실적!$G$2:$G$1297,"멕시코") | D12: =SUMIFS(수출실적!$L$2:$L$1297,수출실적!$C$2:$C$1297,$A12,수출실적!$G$2:$G$1297,"캐나다") | E12: =SUMIFS(수출실적!$L$2:$L$1297,수출실적!$C$2:$C$1297,$A12,수출실적!$G$2:$G$1297,"독일") | F12: =SUMIFS(수출실적!$L$2:$L$1297,수출실적!$C$2:$C$1297,$A12,수출실적!$G$2:$G$1297,"베트남") | G12: =SUMIFS(수출실적!$L$2:$L$1297,수출실적!$C$2:$C$1297,$A12,수출실적!$G$2:$G$1297,"인도") | H12: =SUMIFS(수출실적!$L$2:$L$1297,수출실적!$C$2:$C$1297,$A12,수출실적!$G$2:$G$1297,"중국") | I12: =SUM(B12:H12) | J12: =IF(I11=0,"",I12/I11-1) | K12: =SUMPRODUCT((수출실적!$C$2:$C$1297=$A12)*(수출실적!$L$2:$L$1297=""))
A13: 2023-12 | B13: =SUMIFS(수출실적!$L$2:$L$1297,수출실적!$C$2:$C$1297,$A13,수출실적!$G$2:$G$1297,"미국") | C13: =SUMIFS(수출실적!$L$2:$L$1297,수출실적!$C$2:$C$1297,$A13,수출실적!$G$2:$G$1297,"멕시코") | D13: =SUMIFS(수출실적!$L$2:$L$1297,수출실적!$C$2:$C$1297,$A13,수출실적!$G$2:$G$1297,"캐나다") | E13: =SUMIFS(수출실적!$L$2:$L$1297,수출실적!$C$2:$C$1297,$A13,수출실적!$G$2:$G$1297,"독일") | F13: =SUMIFS(수출실적!$L$2:$L$1297,수출실적!$C$2:$C$1297,$A13,수출실적!$G$2:$G$1297,"베트남") | G13: =SUMIFS(수출실적!$L$2:$L$1297,수출실적!$C$2:$C$1297,$A13,수출실적!$G$2:$G$1297,"인도") | H13: =SUMIFS(수출실적!$L$2:$L$1297,수출실적!$C$2:$C$1297,$A13,수출실적!$G$2:$G$1297,"중국") | I13: =SUM(B13:H13) | J13: =IF(I12=0,"",I13/I12-1) | K13: =SUMPRODUCT((수출실적!$C$2:$C$1297=$A13)*(수출실적!$L$2:$L$1297=""))
A14: 2024-01 | B14: =SUMIFS(수출실적!$L$2:$L$1297,수출실적!$C$2:$C$1297,$A14,수출실적!$G$2:$G$1297,"미국") | C14: =SUMIFS(수출실적!$L$2:$L$1297,수출실적!$C$2:$C$1297,$A14,수출실적!$G$2:$G$1297,"멕시코") | D14: =SUMIFS(수출실적!$L$2:$L$1297,수출실적!$C$2:$C$1297,$A14,수출실적!$G$2:$G$1297,"캐나다") | E14: =SUMIFS(수출실적!$L$2:$L$1297,수출실적!$C$2:$C$1297,$A14,수출실적!$G$2:$G$1297,"독일") | F14: =SUMIFS(수출실적!$L$2:$L$1297,수출실적!$C$2:$C$1297,$A14,수출실적!$G$2:$G$1297,"베트남") | G14: =SUMIFS(수출실적!$L$2:$L$1297,수출실적!$C$2:$C$1297,$A14,수출실적!$G$2:$G$1297,"인도") | H14: =SUMIFS(수출실적!$L$2:$L$1297,수출실적!$C$2:$C$1297,$A14,수출실적!$G$2:$G$1297,"중국") | I14: =SUM(B14:H14) | J14: =IF(I13=0,"",I14/I13-1) | K14: =SUMPRODUCT((수출실적!$C$2:$C$1297=$A14)*(수출실적!$L$2:$L$1297=""))
... A37: 2025-12 | B37: =SUMIFS(수출실적!$L$2:$L$1297,수출실적!$C$2:$C$1297,$A37,수출실적!$G$2:$G$1297,"미국") | C37: =SUMIFS(수출실적!$L$2:$L$1297,수출실적!$C$2:$C$1297,$A37,수출실적!$G$2:$G$1297,"멕시코") | D37: =SUMIFS(수출실적!$L$2:$L$1297,수출실적!$C$2:$C$1297,$A37,수출실적!$G$2:$G$1297,"캐나다") | E37: =SUMIFS(수출실적!$L$2:$L$1297,수출실적!$C$2:$C$1297,$A37,수출실적!$G$2:$G$1297,"독일") | F37: =SUMIFS(수출실적!$L$2:$L$1297,수출실적!$C$2:$C$1297,$A37,수출실적!$G$2:$G$1297,"베트남") | G37: =SUMIFS(수출실적!$L$2:$L$1297,수출실적!$C$2:$C$1297,$A37,수출실적!$G$2:$G$1297,"인도") | H37: =SUMIFS(수출실적!$L$2:$L$1297,수출실적!$C$2:$C$1297,$A37,수출실적!$G$2:$G$1297,"중국") | I37: =SUM(B37:H37) | J37: =IF(I36=0,"",I37/I36-1) | K37: =SUMPRODUCT((수출실적!$C$2:$C$1297=$A37)*(수출실적!$L$2:$L$1297=""))
A39: 금액은 수출실적 시트 합계(SUMIFS). 금액 빈칸은 0으로 더해지므로 '금액 빈칸 행수'가 0이 아닌 달은 합계를 그대로 쓰지 말 것.
A40: 회사 자체 수출 흐름 참고용. 대시보드 안정성(목적국 수입금액 CV·급감)은 공개 무역통계로 계산하며 이 표와 다름.

Sheet 근거
A1: 한빛반도체 생성 근거 — 삼성전자 DS부문 사업보고서 수치를 1/500로 축소한 가상 데이터
A2: 파란 글씨 = 사업보고서 원문 값(입력) · 노란 칸 = 가정값 · 검정 = 수식. 실제 회사의 수출 내역이 아님.
A4: A. 사업보고서 원문 수치
A5: 항목 | B5: 2022 | C5: 2023 | D5: 2024 | E5: 2025 | F5: 단위 | G5: 출처
A6: DS부문 매출액 | B6: 984553 | C6: 665945 | D6: 1110660 | E6: 1301282 | F6: 억원 | G6: 삼성전자 사업보고서(2026.03.10) PDF p.43 '4. 매출 및 수주상황' (제57·56·55기) / 2022: 사업보고서(2024.03.12) PDF p.38
A7: 메모리 매출액 | B7: 685349 | C7: 441254 | D7: 844630 | E7: 1040812 | F7: 억원 | G7: 삼성전자 사업보고서(2026.03.10) PDF p.44 '(1) 주요 제품별 매출실적' / 2022: 사업보고서(2024.03.12) PDF p.39
A8: 별도 내수(국내) | C8: 205196 | D8: 202978 | E8: 216560 | F8: 억원 | G8: 삼성전자 사업보고서(2026.03.10) PDF p.44 '(3) 주요 지역별 매출 현황' (별도 기준, 전사)
A9: 별도 수출-미주 | C9: 510934 | D9: 613533 | E9: 678942 | F9: 억원 | G9: 同上
A10: 별도 수출-유럽 | C10: 239342 | D10: 290967 | E10: 312307 | F10: 억원 | G10: 同上
A11: 별도 수출-아시아·아프리카 | C11: 326262 | D11: 333769 | E11: 456870 | F11: 억원 | G11: 同上
A12: 별도 수출-중국 | C12: 422007 | D12: 649275 | E12: 715751 | F12: 억원 | G12: 同上
A13: 메모리 평균판매가격 전년비 | C13: -0.45 | D13: 0.63 | E13: 0.14 | F13: 비율 | G13: 삼성전자 사업보고서 '주요 제품 등의 가격 변동 현황': 2023 PDF p.30(2024.03.12), 2024 PDF p.30(2025.03.11), 2025 PDF p.35(2026.03.10)
A14: SK하이닉스 DRAM/(DRAM+NAND) 비중 (삼성 미공시 → 대용) | C14: 0.68269184 | D14: 0.69886918 | E14: 0.78356344 | F14: 비율 | G14: SK하이닉스 사업보고서 연결 주석 '매출액' 제품별: 2025·2024 PDF p.143(2026.03.17), 2023 PDF p.143(2025.03.19)
A16: B. 가정값
A17: 가정 | B17: 값 | C17: 2023 | D17: 2024 | E17: 2025 | G17: 설명
A18: 축소 배율 (1/n) | B18: 500 | G18: 가상 중견기업 규모로 맞추기 위한 배율. 두 회사 동일 적용 → 두 회사의 상대 규모는 원문 비율 유지
A19: HBM 비중 (DRAM 중) | C19: 0.1 | D19: 0.2 | E19: 0.3 | G19: 사업보고서에 HBM 매출 비중 수치 없음 → 가정값. HBM 품목을 따로 두려고 넣음
A20: 권역 '미주' 중 미국 비중 | B20: 0.85 | G20: 사업보고서는 권역 단위만 공시 → 국가 배분은 가정
A21: 권역 '미주' 중 멕시코 비중 | B21: 0.1 | G21: 사업보고서는 권역 단위만 공시 → 국가 배분은 가정
A22: 권역 '미주' 중 캐나다 비중 | B22: 0.05 | G22: 사업보고서는 권역 단위만 공시 → 국가 배분은 가정
A23: 권역 '유럽' 대표국 = 독일 | B23: 1 | G23: 권역 전체를 대표 1개국으로 둠 (가정)
A24: 권역 '아시아·아프리카' 중 베트남 비중 | B24: 0.6 | G24: 사업보고서는 권역 단위만 공시 → 국가 배분은 가정
A25: 권역 '아시아·아프리카' 중 인도 비중 | B25: 0.4 | G25: 사업보고서는 권역 단위만 공시 → 국가 배분은 가정
A26: 미국 내 C-HB-01 비중 | B26: 0.65 | G26: 거래처 배분 가정
A27: 미국 내 C-HB-02 비중 | B27: 0.35 | G27: 거래처 배분 가정
A28: 중국 내 C-HB-08 비중 | B28: 0.6 | G28: 거래처 배분 가정
A29: 중국 내 C-HB-09 비중 | B29: 0.4 | G29: 거래처 배분 가정
A30: 단가·중량·월별 흐름 | B30: 제품정보 참조 | G30: 2023년 평균 기준단가(가정) × 메모리 판매가격 지수(A의 전년비로 연결) · 월별 흐름은 연간 값을 연중 가운데에 두고 로그선형 보간 + ±9% 흔들림(시드 고정) 후 연간 합계를 원문 비율에 맞춤
A31: 운송수단 | B31: 항공 기본 | G31: NAND의 중국·베트남 선적만 해상(부산항), 나머지 인천공항 항공 — 가정
A33: C. 산출 — 연간 수출 목표액과 비중
A34: 산출 항목 | C34: 2023 | D34: 2024 | E34: 2025 | F34: 단위 | G34: 계산
A35: 수출 비중 (별도 기준 전사 비율 대용) | C35: =(C9+C10+C11+C12)/((C9+C10+C11+C12)+C8) | D35: =(D9+D10+D11+D12)/((D9+D10+D11+D12)+D8) | E35: =(E9+E10+E11+E12)/((E9+E10+E11+E12)+E8) | G35: DS부문 단독 지역별 매출은 미공시 → 전사 별도 기준 수출비중을 DS부문에 적용
A36: 연간 수출 목표액 | C36: =C6*C35*100000000/$B$18 | D36: =D6*D35*100000000/$B$18 | E36: =E6*E35*100000000/$B$18 | F36: 원 | G36: DS부문 매출액 × 수출 비중 ÷ 축소 배율
A37: 권역 비중 — 미주 | C37: =C9/(C9+C10+C11+C12) | D37: =D9/(D9+D10+D11+D12) | E37: =E9/(E9+E10+E11+E12)
A38: 권역 비중 — 유럽 | C38: =C10/(C9+C10+C11+C12) | D38: =D10/(D9+D10+D11+D12) | E38: =E10/(E9+E10+E11+E12)
A39: 권역 비중 — 아시아·아프리카 | C39: =C11/(C9+C10+C11+C12) | D39: =D11/(D9+D10+D11+D12) | E39: =E11/(E9+E10+E11+E12)
A40: 권역 비중 — 중국 | C40: =C12/(C9+C10+C11+C12) | D40: =D12/(D9+D10+D11+D12) | E40: =E12/(E9+E10+E11+E12)
A41: 제품 비중 — 비메모리(모바일AP) | C41: =1-C7/C6 | D41: =1-D7/D6 | E41: =1-E7/E6
A43: D. 재구성 검증 — 수출실적 시트 합계가 C의 목표액과 맞는지
A44: 검증 항목 | C44: 2023 | D44: 2024 | E44: 2025 | F44: 단위 | G44: 설명
...
