Workbook

Sheet 기업정보
A1: 시연용 가상 데이터. 실제 기업 자료가 아님
A3: template_version | B3: 0.2
A4: company | B4: 새벽반도체
A5: company_en | B5: Saebyeok Semiconductor
A6: data_class | B6: 가상데이터
A7: 기준기간 | B7: 2023-01 ~ 2025-12 (월별, 일부 달 자료 없음)
A8: 금액 통화
A9: 환산 환율 | B9: FRED H.10 EXKOUS 원/달러 월평균 (junhee/data/raw/external/fred_EXKOUS_krw_per_usd_monthly.csv)
A10: 생성 근거 | B10: 근거 자료 없음 — 결측치 처리 시연용으로 임의 생성한 가상 회사 (사업보고서 기반 아님)
A11: 작성일 | B11: 2026-09-26
A13: 대시보드 항목 ↔ 이 파일의 입력값
A14: 대시보드 항목 | B14: 이 파일에서 쓰는 값 | C14: 공개자료·API 쪽에서 붙는 값 (이 파일에는 없음)
A15: 공통 | B15: 회사·제품명(제품정보), 입력 HSK와 분석 HS6(제품정보), 목적국(수출실적·거래처), 자료기간(기준기간) | C15: 기준일·출처는 공개자료 쪽
A16: 1. 규제 | B16: 제품정보.입력HSK → HSK 연계표 통제번호 후보 / 거래처.법인명·주소 → CSL 검색 | C16: 통제번호·품목명, 목적국 수입규제 기록, CSL 명단 (발견 사실만 표시, '없음'을 '규제 없음'으로 판정하지 않음)
A17: 2. 시장성 | B17: 수출실적의 목적국·HS·월별 금액(회사 수출 흐름, 월별집계 시트) | C17: 목적국 총수입, 한국의 해당국 수출, 성장률, 한국산 점유율, WSTS 업황
A18: 3. 가격 | B18: 수출실적의 금액·순중량(kg) → 회사 kg당 단가 / 통화 → 참고환율 통화 선택 | C18: 무역통계 단가, 관세 참고치(WTO), 참고환율, 수출입물가지수, 운송비 참고
A19: 4. 물류 | B19: 물류 시트의 출발지·도착지 코드(공항 IATA·항만 UN/LOCODE)와 선적일 → 운항·입출항 조회 조건 / 예정·실제 도착일 → 납기 준수율·리드타임 / 운임(USD) → 운송비 비중 (v0.3 추가, 가정값) | C19: 인천공항 화물편 일정·운항 횟수, 선박 입출항 기록 (직항·배송시간은 확정하지 않음)
A20: 5. 안정성 | B20: 월별집계 시트의 월별 금액·전월대비(회사 수출 변동 참고) | C20: 목적국 월별 수입금액, CV, 급감 이력, 환율 변동성
A21: 제외 | B21: 원가·이익률, 허가·인증 충족 여부 — 이 파일에 넣지 않음 (납기·운임은 시연용 가정값으로 물류 시트에 추가) | C21: 팀 공유 문서 '이번 기본 범위에서 제외할 항목'
A23: 의도적으로 넣은 결측·예외 위치는 '결측목록' 시트에 전부 기록했습니다. 빈칸을 0이나 임의 값으로 채우지 않습니다.
A24: 금액 통화(기업정보 B8)도 일부러 비워 둔 결측 항목입니다.

Sheet 제품정보
A1: 제품ID | B1: 모델명 | C1: 제품군 | D1: 입력HSK | E1: HS코드 | F1: HS버전 | G1: 제조국 | H1: 사양 | I1: 단위 | J1: 단위중량(g) | K1: 분류비고
A2: P-SB-001 | B2: SBM-32 | C2: 시스템반도체(MCU) | D2: 8542311000 | E2: 854231 | F2: HS2022 | G2: 대한민국 | H2: 32bit MCU 저전력 | I2: EA | J2: 0.35
A3: P-SB-002 | B3: SBE-64 | C3: NAND(eMMC) | D3: 8542321030 | E3: 854232 | F3: HS2022 | G3: 대한민국 | H3: eMMC 5.1 64GB | I3: EA | J3: 0.9
A4: P-SB-003 | B4: SBP-12 | C4: 전원관리 IC | F4: HS2022 | G4: 대한민국 | H4: PMIC 12채널 | I4: EA | J4: 0.25 | K4: HS 미확인 — 입력HSK·HS코드 비어 있음 (결측)

Sheet 거래처
A1: 거래처ID | B1: 법인명 | C1: 별칭 | D1: 주소 | E1: 도시 | F1: 국가 | G1: 국가코드 | H1: 최종사용자관계
A2: C-SB-01 | B2: Blue Mesa Controls Inc. | C2: 블루메사 컨트롤즈 | D2: 3100 Mesa Dr, Austin, TX 78731 | E2: Austin | F2: 미국 | G2: US | H2: 최종사용자
A3: C-SB-02 | B3: Monterrey Electrónica S.A. | C3: 몬테레이 일렉트로니카 | D3: Av. Constitución 450, Monterrey, N.L. | E3: Monterrey | F3: 멕시코 | G3: MX | H3: 최종사용자
A4: C-SB-03 | B4: Da Nang Smart Devices Co., Ltd. | C4: 다낭 스마트 디바이스 | E4: Da Nang | F4: 베트남 | G4: VN | H4: 최종사용자
A5: C-SB-04 | C5: 푸네 오토 일렉트릭 | D5: Chakan MIDC, Pune, Maharashtra | E5: Pune | F5: 인도 | G5: IN | H5: 유통업체

Sheet 수출실적
A1: 실적ID | B1: 거래일 | C1: 거래월 | D1: 연도 | E1: 제품ID | F1: 거래처ID | G1: 목적국 | H1: 목적국코드 | I1: 수량 | J1: 단위 | K1: 순중량(kg) | L1: 금액 | M1: 통화 | N1: 인코텀즈 | O1: 취소반품 | P1: 적용환율(KRW/USD) | Q1: 원화환산(원)
A2: R-SB-0001 | B2: 44931 | C2: 2023-01 | D2: 2023 | E2: P-SB-003 | F2: C-SB-04 | G2: 인도 | H2: IN | I2: 0 | J2: EA | K2: 0 | L2: 0 | M2: USD | N2: FOB | O2: Y | P2: 1243.0705 | Q2: =IF(OR(L2="",M2="",P2=""),"",L2*P2)
A3: R-SB-0002 | B3: 44940 | C3: 2023-01 | D3: 2023 | F3: C-SB-02 | G3: 멕시코 | H3: MX | I3: 14887 | J3: EA | K3: 13.4 | L3: 60841.25 | M3: USD | N3: FOB | O3: N | P3: 1243.0705 | Q3: =IF(OR(L3="",M3="",P3=""),"",L3*P3)
A4: R-SB-0003 | B4: 44941 | C4: 2023-01 | D4: 2023 | E4: P-SB-003 | F4: C-SB-02 | G4: 멕시코 | H4: MX | I4: 0 | J4: EA | K4: 0 | L4: 0 | M4: USD | N4: FOB | O4: Y | P4: 1243.0705 | Q4: =IF(OR(L4="",M4="",P4=""),"",L4*P4)
A5: R-SB-0004 | B5: 44944 | C5: 2023-01 | D5: 2023 | E5: P-SB-001 | F5: C-SB-03 | G5: 베트남 | H5: VN | I5: 57829 | J5: EA | K5: 20.24 | L5: 103613.39 | M5: USD | N5: FOB | O5: N | P5: 1243.0705 | Q5: =IF(OR(L5="",M5="",P5=""),"",L5*P5)
A6: R-SB-0005 | B6: 44944 | C6: 2023-01 | D6: 2023 | E6: P-SB-002 | F6: C-SB-04 | G6: 인도 | H6: IN | I6: 6980 | J6: EA | K6: 6.28 | L6: 28119.93 | M6: USD | N6: FOB | O6: N | P6: 1243.0705 | Q6: =IF(OR(L6="",M6="",P6=""),"",L6*P6)
A7: R-SB-0006 | B7: 44945 | C7: 2023-01 | D7: 2023 | E7: P-SB-001 | F7: C-SB-02 | G7: 멕시코 | H7: MX | I7: 62497 | J7: EA | K7: 21.87 | L7: 115042.04 | M7: USD | N7: FOB | O7: N | P7: 1243.0705 | Q7: =IF(OR(L7="",M7="",P7=""),"",L7*P7)
A8: R-SB-0007 | B8: 44948 | C8: 2023-01 | D8: 2023 | E8: P-SB-001 | F8: C-SB-01 | G8: 미국 | H8: US | I8: 87729 | J8: EA | K8: 30.71 | L8: 162868.67 | M8: USD | N8: FOB | O8: N | P8: 1243.0705 | Q8: =IF(OR(L8="",M8="",P8=""),"",L8*P8)
A9: R-SB-0008 | B9: 44950 | C9: 2023-01 | D9: 2023 | E9: P-SB-002 | F9: C-SB-01 | G9: 미국 | H9: US | I9: 25855 | J9: EA | L9: 103227.01 | M9: USD | N9: FOB | O9: N | P9: 1243.0705 | Q9: =IF(OR(L9="",M9="",P9=""),"",L9*P9)
A10: R-SB-0009 | B10: 44951 | C10: 2023-01 | D10: 2023 | E10: P-SB-003 | F10: C-SB-03 | G10: 베트남 | H10: VN | I10: 30306 | J10: EA | K10: 7.58 | L10: 28038.29 | M10: USD | N10: FOB | O10: N | P10: 1243.0705 | Q10: =IF(OR(L10="",M10="",P10=""),"",L10*P10)
A11: R-SB-0010 | B11: 44953 | C11: 2023-01 | D11: 2023 | E11: P-SB-002 | F11: C-SB-03 | G11: 베트남 | H11: VN | I11: 10239 | J11: EA | K11: 9.22 | L11: 40256.83 | M11: USD | N11: FOB | O11: N | P11: 1243.0705 | Q11: =IF(OR(L11="",M11="",P11=""),"",L11*P11)
A12: R-SB-0010 | B12: 44953 | C12: 2023-01 | D12: 2023 | E12: P-SB-002 | F12: C-SB-03 | G12: 베트남 | H12: VN | I12: 10239 | J12: EA | K12: 9.22 | L12: 40256.83 | M12: USD | N12: FOB | O12: N | P12: 1243.0705 | Q12: =IF(OR(L12="",M12="",P12=""),"",L12*P12)
A13: R-SB-0011 | B13: 44953 | C13: 2023-01 | D13: 2023 | E13: P-SB-001 | F13: C-SB-04 | G13: 인도 | H13: IN | I13: 29897 | J13: EA | K13: 10.46 | L13: 52492.02 | M13: USD | N13: FOB | O13: N | P13: 1243.0705 | Q13: =IF(OR(L13="",M13="",P13=""),"",L13*P13)
A14: R-SB-0012 | B14: 44970 | C14: 2023-02 | D14: 2023 | E14: P-SB-001 | F14: C-SB-03 | G14: 베트남 | H14: VN | I14: 42947 | J14: EA | K14: 15.03 | M14: USD | N14: FOB | O14: N | P14: 1275.4205 | Q14: =IF(OR(L14="",M14="",P14=""),"",L14*P14)
A15: R-SB-0013 | B15: 44973 | C15: 2023-02 | D15: 2023 | E15: P-SB-001 | F15: C-SB-01 | G15: 미국 | H15: US | I15: 129045 | J15: EA | K15: 45.17 | L15: 241961.89 | M15: USD | N15: FOB | O15: N | P15: 1275.4205 | Q15: =IF(OR(L15="",M15="",P15=""),"",L15*P15)
A16: R-SB-0014 | B16: 44973 | C16: 2023-02 | D16: 2023 | E16: P-SB-002 | F16: C-SB-03 | G16: 베트남 | H16: VN | I16: 10568 | J16: EA | K16: 9.51 | M16: USD | N16: FOB | O16: N | P16: 1275.4205 | Q16: =IF(OR(L16="",M16="",P16=""),"",L16*P16)
A17: R-SB-0015 | B17: 44973 | C17: 2023-02 | D17: 2023 | E17: P-SB-002 | F17: C-SB-04 | G17: 인도 | H17: IN | I17: 5904 | J17: EA | K17: 5.31 | L17: 23372.32 | M17: USD | N17: FOB | O17: N | P17: 1275.4205 | Q17: =IF(OR(L17="",M17="",P17=""),"",L17*P17)
A18: R-SB-0016 | B18: 44974 | C18: 2023-02 | D18: 2023 | E18: P-SB-001 | F18: C-SB-02 | G18: 멕시코 | H18: MX | I18: 61785 | J18: EA | K18: 21.62 | L18: 116547.02 | M18: USD | N18: FOB | O18: N | P18: 1275.4205 | Q18: =IF(OR(L18="",M18="",P18=""),"",L18*P18)
A19: R-SB-0017 | B19: 44974 | C19: 2023-02 | D19: 2023 | E19: P-SB-003 | F19: C-SB-02 | G19: 멕시코 | H19: MX | I19: 41915 | J19: EA | K19: 10.48 | L19: 37597.31 | M19: USD | N19: FOB | O19: N | P19: 1275.4205 | Q19: =IF(OR(L19="",M19="",P19=""),"",L19*P19)
A20: R-SB-0018 | B20: 44975 | C20: 2023-02 | D20: 2023 | E20: P-SB-003 | F20: C-SB-04 | G20: 인도 | H20: IN | I20: 13015 | J20: EA | L20: 11653.49 | M20: USD | N20: FOB | O20: N | P20: 1275.4205 | Q20: =IF(OR(L20="",M20="",P20=""),"",L20*P20)
A21: R-SB-0019 | B21: 44978 | C21: 2023-02 | D21: 2023 | E21: P-SB-002 | F21: C-SB-02 | G21: 멕시코 | H21: MX | I21: 17504 | J21: EA | L21: 66739.05 | M21: USD | N21: FOB | O21: N | P21: 1275.4205 | Q21: =IF(OR(L21="",M21="",P21=""),"",L21*P21)
A22: R-SB-0020 | B22: 44978 | C22: 2023-02 | D22: 2023 | E22: P-SB-003 | F22: C-SB-03 | G22: 베트남 | H22: VN | I22: 23980 | J22: EA | K22: 6 | L22: 22321.39 | M22: USD | N22: FOB | O22: N | P22: 1275.4205 | Q22: =IF(OR(L22="",M22="",P22=""),"",L22*P22)
A23: R-SB-0021 | B23: 44980 | C23: 2023-02 | D23: 2023 | E23: P-SB-003 | F23: C-SB-01 | G23: 미국 | H23: US | I23: 81466 | J23: EA | K23: 20.37 | L23: 70792.35 | M23: USD | N23: FOB | O23: N | P23: 1275.4205 | Q23: =IF(OR(L23="",M23="",P23=""),"",L23*P23)
A24: R-SB-0022 | B24: 44990 | C24: 2023-03 | D24: 2023 | E24: P-SB-001 | F24: C-SB-02 | G24: 멕시코 | H24: MX | I24: 76671 | J24: EA | K24: 26.83 | M24: USD | N24: FOB | O24: N | P24: 1306.0161 | Q24: =IF(OR(L24="",M24="",P24=""),"",L24*P24)
A25: R-SB-0023 | B25: 44991 | C25: 2023-03 | D25: 2023 | E25: P-SB-003 | F25: C-SB-04 | G25: 인도 | H25: IN | I25: 13848 | J25: EA | K25: 3.46 | L25: 12482 | M25: USD | N25: FOB | O25: N | P25: 1306.0161 | Q25: =IF(OR(L25="",M25="",P25=""),"",L25*P25)
A26: R-SB-0024 | B26: 44994 | C26: 2023-03 | D26: 2023 | E26: P-SB-001 | F26: C-SB-01 | G26: 미국 | H26: US | J26: EA | K26: 49.49 | L26: 255934.2 | M26: USD | N26: FOB | O26: N | P26: 1306.0161 | Q26: =IF(OR(L26="",M26="",P26=""),"",L26*P26)
A27: R-SB-0025 | B27: 44996 | C27: 2023-03 | D27: 2023 | E27: P-SB-001 | F27: C-SB-03 | G27: 베트남 | H27: VN | I27: 46200 | J27: EA | K27: 16.17 | L27: 85849.7 | M27: USD | N27: FOB | O27: N | P27: 1306.0161 | Q27: =IF(OR(L27="",M27="",P27=""),"",L27*P27)
A28: R-SB-0026 | B28: 44997 | C28: 2023-03 | D28: 2023 | E28: P-SB-002 | F28: C-SB-03 | G28: 베트남 | H28: VN | I28: 15411 | J28: EA | K28: 13.87 | L28: 59061.77 | M28: USD | N28: FOB | O28: N | P28: 1306.0161 | Q28: =IF(OR(L28="",M28="",P28=""),"",L28*P28)
A29: R-SB-0027 | B29: 44998 | C29: 2023-03 | D29: 2023 | E29: P-SB-003 | F29: C-SB-01 | G29: 미국 | H29: US | I29: 59526 | J29: EA | K29: 14.88 | L29: 55115.17 | M29: USD | N29: FOB | O29: N | P29: 1306.0161 | Q29: =IF(OR(L29="",M29="",P29=""),"",L29*P29)
A30: R-SB-0028 | B30: 45001 | C30: 2023-03 | D30: 2023 | E30: P-SB-003 | F30: C-SB-03 | G30: 베트남 | H30: VN | I30: 23887 | J30: EA | K30: 5.97 | L30: 22305 | M30: USD | N30: FOB | O30: N | P30: 1306.0161 | Q30: =IF(OR(L30="",M30="",P30=""),"",L30*P30)
A31: R-SB-0029 | B31: 45001 | C31: 2023-03 | D31: 2023 | E31: P-SB-002 | F31: C-SB-04 | G31: 인도 | H31: IN | I31: 5192 | J31: EA | K31: 4.67 | L31: 21493.95 | M31: USD | N31: FOB | O31: N | P31: 1306.0161 | Q31: =IF(OR(L31="",M31="",P31=""),"",L31*P31)
A32: R-SB-0030 | B32: 45007 | C32: 2023-03 | D32: 2023 | E32: P-SB-002 | F32: C-SB-01 | G32: 미국 | H32: US | I32: 26338 | J32: EA | K32: 23.7 | L32: 105084.15 | M32: USD | N32: FOB | O32: N | P32: 1306.0161 | Q32: =IF(OR(L32="",M32="",P32=""),"",L32*P32)
A33: R-SB-0031 | B33: 45008 | C33: 2023-03 | D33: 2023 | E33: P-SB-003 | F33: C-SB-02 | G33: 멕시코 | H33: MX | I33: 47060 | J33: EA | K33: 11.77 | L33: 40729.18 | M33: USD | N33: FOB | O33: N | P33: 1306.0161 | Q33: =IF(OR(L33="",M33="",P33=""),"",L33*P33)
A34: R-SB-0032 | B34: 45012 | C34: 2023-03 | D34: 2023 | E34: P-SB-002 | F34: C-SB-02 | G34: 멕시코 | H34: MX | I34: 13810 | J34: EA | K34: 12.43 | L34: 54844.58 | M34: USD | N34: FOB | O34: N | P34: 1306.0161 | Q34: =IF(OR(L34="",M34="",P34=""),"",L34*P34)
A35: R-SB-0033 | B35: 45019 | C35: 2023-04 | D35: 2023 | E35: P-SB-001 | F35: C-SB-04 | G35: 인도 | H35: IN | I35: 28955 | J35: EA | K35: 10.13 | L35: 53534.27 | M35: USD | N35: FOB | O35: N | P35: 1322.057 | Q35: =IF(OR(L35="",M35="",P35=""),"",L35*P35)
A36: R-SB-0034 | B36: 45027 | C36: 2023-04 | D36: 2023 | E36: P-SB-002 | F36: C-SB-04 | G36: 인도 | H36: IN | I36: 5863 | J36: EA | K36: 5.28 | L36: 23148.7 | M36: USD | N36: FOB | O36: N | P36: 1322.057 | Q36: =IF(OR(L36="",M36="",P36=""),"",L36*P36)
A37: R-SB-0035 | B37: 45028 | C37: 2023-04 | D37: 2023 | E37: P-SB-003 | F37: C-SB-02 | G37: 멕시코 | H37: MX | I37: 40500 | J37: EA | K37: 10.12 | L37: 38145.77 | M37: USD | N37: FOB | O37: N | P37: 1322.057 | Q37: =IF(OR(L37="",M37="",P37=""),"",L37*P37)
A38: R-SB-0036 | B38: 45031 | C38: 2023-04 | D38: 2023 | E38: P-SB-003 | F38: C-SB-03 | G38: 베트남 | H38: VN | I38: 26225 | J38: EA | K38: 6.56 | L38: 22576.68 | M38: USD | N38: FOB | O38: N | P38: 1322.057 | Q38: =IF(OR(L38="",M38="",P38=""),"",L38*P38)
... A44: R-SB-0042 | B44: 45050 | C44: 2023-05 | D44: 2023 | E44: P-SB-001 | F44: C-SB-04 | G44: 인도 | H44: IN | I44: 20127 | J44: EA | K44: 7.04 | L44: 37929.9 | M44: USD | N44: FOB | O44: N | P44: 1327.48 | Q44: =IF(OR(L44="",M44="",P44=""),"",L44*P44)
A45: R-SB-0043 | B45: 45051 | C45: 2023-05 | D45: 2023 | E45: P-SB-001 | F45: C-SB-01 | G45: 미국 | H45: US | I45: 129953 | J45: EA | K45: 45.48 | M45: USD | N45: FOB | O45: N | P45: 1327.48 | Q45: =IF(OR(L45="",M45="",P45=""),"",L45*P45)
...

Sheet 물류
A1: 물류ID | B1: 실적ID | C1: 운송수단 | D1: 출발지 | E1: 출발지코드 | F1: 도착지 | G1: 도착지코드 | H1: 선적일 | I1: 예정도착일 | J1: 실제도착일 | K1: 운임(USD)
A2: L-SB-0001 | B2: R-SB-0001 | C2: 항공 | D2: 인천공항 | E2: ICN | F2: 뭄바이공항 | G2: BOM | H2: 44931 | I2: 44934
A3: L-SB-0002 | B3: R-SB-0002 | C3: 항공 | D3: 인천공항 | E3: ICN | F3: 몬테레이공항 | G3: MTY | H3: 44940 | I3: 44943 | J3: 44943 | K3: 135
A4: L-SB-0003 | B4: R-SB-0003 | C4: 항공 | D4: 인천공항 | E4: ICN | F4: 몬테레이공항 | G4: MTY | H4: 44941 | I4: 44945
A5: L-SB-0004 | B5: R-SB-0004 | C5: 항공 | D5: 인천공항 | E5: ICN | F5: 다낭공항 | G5: DAD | H5: 44944 | I5: 44947 | J5: 44947 | K5: 164.28
A6: L-SB-0005 | B6: R-SB-0005 | C6: 항공 | D6: 인천공항 | E6: ICN | F6: 뭄바이공항 | G6: BOM | H6: 44944 | I6: 44948 | J6: 44948 | K6: 135
A7: L-SB-0006 | B7: R-SB-0006 | C7: 항공 | D7: 인천공항 | E7: ICN | F7: 몬테레이공항 | G7: MTY | H7: 44945 | I7: 44948 | J7: 44952 | K7: 159.17
A8: L-SB-0007 | B8: R-SB-0007 | C8: 항공 | D8: 인천공항 | E8: ICN | F8: 댈러스공항 | G8: DFW | H8: 44948 | I8: 44953 | J8: 44953 | K8: 236.19
A9: L-SB-0008 | B9: R-SB-0008 | C9: 항공 | D9: 인천공항 | E9: ICN | F9: 댈러스공항 | G9: DFW | H9: 44950 | I9: 44954 | J9: 44953
A10: L-SB-0009 | B10: R-SB-0009 | C10: 항공 | D10: 인천공항 | E10: ICN | F10: 다낭공항 | G10: DAD | H10: 44951 | I10: 44956 | J10: 44955 | K10: 135
A11: L-SB-0010 | B11: R-SB-0010 | C11: 해상 | D11: 부산항 | E11: KRPUS | F11: 다낭항 | G11: VNDAD | H11: 44953 | I11: 44975 | J11: 44974 | K11: 530
A12: L-SB-0011 | B12: R-SB-0010 | C12: 해상 | D12: 부산항 | E12: KRPUS | F12: 다낭항 | G12: VNDAD | H12: 44953 | I12: 44976 | J12: 44976 | K12: 530
A13: L-SB-0012 | B13: R-SB-0011 | C13: 항공 | D13: 인천공항 | E13: ICN | F13: 뭄바이공항 | G13: BOM | H13: 44953 | I13: 44956 | J13: 44956 | K13: 135
A14: L-SB-0013 | B14: R-SB-0012 | C14: 항공 | D14: 인천공항 | E14: ICN | F14: 다낭공항 | G14: DAD | H14: 44970 | I14: 44973 | J14: 44973 | K14: 135
A15: L-SB-0014 | B15: R-SB-0013 | C15: 항공 | D15: 인천공항 | E15: ICN | F15: 댈러스공항 | G15: DFW | H15: 44973 | I15: 44978 | J15: 44977 | K15: 316.08
A16: L-SB-0015 | B16: R-SB-0014 | C16: 해상 | D16: 부산항 | E16: KRPUS | F16: 다낭항 | G16: VNDAD | H16: 44973 | I16: 44993 | J16: 44993 | K16: 530
A17: L-SB-0016 | B17: R-SB-0015 | C17: 항공 | D17: 인천공항 | E17: ICN | F17: 뭄바이공항 | G17: BOM | H17: 44973 | I17: 44975 | J17: 44975 | K17: 135
A18: L-SB-0017 | B18: R-SB-0016 | C18: 항공 | D18: 인천공항 | E18: ICN | F18: 몬테레이공항 | H18: 44974 | I18: 44978 | J18: 44978 | K18: 156.06
A19: L-SB-0018 | B19: R-SB-0017 | C19: 항공 | D19: 인천공항 | E19: ICN | F19: 몬테레이공항 | H19: 44974 | I19: 44977 | J19: 44977 | K19: 135
A20: L-SB-0019 | B20: R-SB-0018 | C20: 항공 | D20: 인천공항 | E20: ICN | F20: 뭄바이공항 | G20: BOM | H20: 44975 | I20: 44978 | J20: 44978
A21: L-SB-0020 | B21: R-SB-0019 | C21: 항공 | D21: 인천공항 | E21: ICN | F21: 몬테레이공항 | G21: MTY | H21: 44978 | I21: 44981 | J21: 44980
A22: L-SB-0021 | B22: R-SB-0020 | C22: 항공 | D22: 인천공항 | E22: ICN | F22: 다낭공항 | H22: 44978 | J22: 44982 | K22: 135
A23: L-SB-0022 | B23: R-SB-0021 | C23: 항공 | D23: 인천공항 | E23: ICN | F23: 댈러스공항 | G23: DFW | K23: 158.92
A24: L-SB-0023 | B24: R-SB-0022 | C24: 항공 | D24: 인천공항 | E24: ICN | F24: 몬테레이공항 | G24: MTY | H24: 44990 | J24: 44993 | K24: 197.65
A25: L-SB-0024 | B25: R-SB-0023 | C25: 항공 | D25: 인천공항 | E25: ICN | F25: 뭄바이공항 | G25: BOM | K25: 135
A26: L-SB-0025 | B26: R-SB-0024 | C26: 항공 | D26: 인천공항 | E26: ICN | F26: 댈러스공항 | G26: DFW | H26: 44994 | I26: 44999 | J26: 44998 | K26: 322.91
A27: L-SB-0026 | B27: R-SB-0025 | D27: 인천공항 | E27: ICN | F27: 다낭공항 | G27: DAD | H27: 44996 | I27: 45000 | J27: 45000 | K27: 137.97
A28: L-SB-0027 | B28: R-SB-0026 | C28: 해상 | D28: 부산항 | E28: KRPUS | F28: 다낭항 | G28: VNDAD | H28: 44997 | I28: 45020 | J28: 45019 | K28: 530
A29: L-SB-0028 | B29: R-SB-0027 | C29: 항공 | D29: 인천공항 | E29: ICN | F29: 댈러스공항 | G29: DFW | H29: 44998 | I29: 45002 | J29: 45001 | K29: 135
A30: L-SB-0029 | B30: R-SB-0028 | C30: 항공 | D30: 인천공항 | E30: ICN | F30: 다낭공항 | G30: DAD | H30: 45001 | I30: 45005 | J30: 45005 | K30: 135
A31: L-SB-0030 | B31: R-SB-0029 | C31: 항공 | D31: 인천공항 | E31: ICN | F31: 뭄바이공항 | G31: BOM | H31: 45001 | I31: 45004 | J31: 45003 | K31: 135
A32: L-SB-0031 | B32: R-SB-0030 | C32: 항공 | D32: 인천공항 | E32: ICN | F32: 댈러스공항 | G32: DFW | H32: 45007 | I32: 45011 | J32: 45011 | K32: 185.7
A33: L-SB-0032 | B33: R-SB-0031 | C33: 항공 | D33: 인천공항 | E33: ICN | F33: 몬테레이공항 | G33: MTY | H33: 45008 | I33: 45011 | J33: 45013 | K33: 135
A34: L-SB-0033 | B34: R-SB-0032 | C34: 항공 | D34: 인천공항 | E34: ICN | F34: 몬테레이공항 | G34: MTY | H34: 45012 | I34: 45016 | J34: 45016 | K34: 135
A35: L-SB-0034 | B35: R-SB-0033 | C35: 항공 | D35: 인천공항 | E35: ICN | F35: 뭄바이공항 | G35: BOM | H35: 45019 | I35: 45021 | J35: 45021 | K35: 135
A36: L-SB-0035 | B36: R-SB-0034 | C36: 항공 | D36: 인천공항 | E36: ICN | F36: 뭄바이공항 | G36: BOM | H36: 45027 | I36: 45029 | J36: 45028 | K36: 135
A37: L-SB-0036 | B37: R-SB-0035 | C37: 항공 | D37: 인천공항 | E37: ICN | F37: 몬테레이공항 | G37: MTY | H37: 45028 | I37: 45033 | J37: 45033 | K37: 135
A38: L-SB-0037 | B38: R-SB-0036 | C38: 항공 | D38: 인천공항 | E38: ICN | F38: 다낭공항 | G38: DAD | H38: 45031 | I38: 45034 | J38: 45034 | K38: 135
A39: L-SB-0038 | B39: R-SB-0037 | C39: 항공 | D39: 인천공항 | E39: ICN | F39: 댈러스공항 | G39: DFW | H39: 45033 | I39: 45037 | J39: 45036 | K39: 355.89
... A60: L-SB-0059 | B60: R-SB-0058 | C60: 항공 | D60: 인천공항 | E60: ICN | F60: 뭄바이공항 | G60: BOM | H60: 45087 | I60: 45089 | J60: 45089 | K60: 135
...

Sheet 월별집계
A1: 거래월 | B1: 미국 (USD) | C1: 멕시코 (USD) | D1: 베트남 (USD) | E1: 인도 (USD) | F1: 합계 (USD) | G1: 전월대비 | H1: 금액 빈칸 행수
A2: 2023-01 | B2: =SUMIFS(수출실적!$L$2:$L$359,수출실적!$C$2:$C$359,$A2,수출실적!$G$2:$G$359,"미국") | C2: =SUMIFS(수출실적!$L$2:$L$359,수출실적!$C$2:$C$359,$A2,수출실적!$G$2:$G$359,"멕시코") | D2: =SUMIFS(수출실적!$L$2:$L$359,수출실적!$C$2:$C$359,$A2,수출실적!$G$2:$G$359,"베트남") | E2: =SUMIFS(수출실적!$L$2:$L$359,수출실적!$C$2:$C$359,$A2,수출실적!$G$2:$G$359,"인도") | F2: =SUM(B2:E2) | H2: =SUMPRODUCT((수출실적!$C$2:$C$359=$A2)*(수출실적!$L$2:$L$359=""))
A3: 2023-02 | B3: =SUMIFS(수출실적!$L$2:$L$359,수출실적!$C$2:$C$359,$A3,수출실적!$G$2:$G$359,"미국") | C3: =SUMIFS(수출실적!$L$2:$L$359,수출실적!$C$2:$C$359,$A3,수출실적!$G$2:$G$359,"멕시코") | D3: =SUMIFS(수출실적!$L$2:$L$359,수출실적!$C$2:$C$359,$A3,수출실적!$G$2:$G$359,"베트남") | E3: =SUMIFS(수출실적!$L$2:$L$359,수출실적!$C$2:$C$359,$A3,수출실적!$G$2:$G$359,"인도") | F3: =SUM(B3:E3) | G3: =IF(F2=0,"",F3/F2-1) | H3: =SUMPRODUCT((수출실적!$C$2:$C$359=$A3)*(수출실적!$L$2:$L$359=""))
A4: 2023-03 | B4: =SUMIFS(수출실적!$L$2:$L$359,수출실적!$C$2:$C$359,$A4,수출실적!$G$2:$G$359,"미국") | C4: =SUMIFS(수출실적!$L$2:$L$359,수출실적!$C$2:$C$359,$A4,수출실적!$G$2:$G$359,"멕시코") | D4: =SUMIFS(수출실적!$L$2:$L$359,수출실적!$C$2:$C$359,$A4,수출실적!$G$2:$G$359,"베트남") | E4: =SUMIFS(수출실적!$L$2:$L$359,수출실적!$C$2:$C$359,$A4,수출실적!$G$2:$G$359,"인도") | F4: =SUM(B4:E4) | G4: =IF(F3=0,"",F4/F3-1) | H4: =SUMPRODUCT((수출실적!$C$2:$C$359=$A4)*(수출실적!$L$2:$L$359=""))
A5: 2023-04 | B5: =SUMIFS(수출실적!$L$2:$L$359,수출실적!$C$2:$C$359,$A5,수출실적!$G$2:$G$359,"미국") | C5: =SUMIFS(수출실적!$L$2:$L$359,수출실적!$C$2:$C$359,$A5,수출실적!$G$2:$G$359,"멕시코") | D5: =SUMIFS(수출실적!$L$2:$L$359,수출실적!$C$2:$C$359,$A5,수출실적!$G$2:$G$359,"베트남") | E5: =SUMIFS(수출실적!$L$2:$L$359,수출실적!$C$2:$C$359,$A5,수출실적!$G$2:$G$359,"인도") | F5: =SUM(B5:E5) | G5: =IF(F4=0,"",F5/F4-1) | H5: =SUMPRODUCT((수출실적!$C$2:$C$359=$A5)*(수출실적!$L$2:$L$359=""))
A6: 2023-05 | B6: =SUMIFS(수출실적!$L$2:$L$359,수출실적!$C$2:$C$359,$A6,수출실적!$G$2:$G$359,"미국") | C6: =SUMIFS(수출실적!$L$2:$L$359,수출실적!$C$2:$C$359,$A6,수출실적!$G$2:$G$359,"멕시코") | D6: =SUMIFS(수출실적!$L$2:$L$359,수출실적!$C$2:$C$359,$A6,수출실적!$G$2:$G$359,"베트남") | E6: =SUMIFS(수출실적!$L$2:$L$359,수출실적!$C$2:$C$359,$A6,수출실적!$G$2:$G$359,"인도") | F6: =SUM(B6:E6) | G6: =IF(F5=0,"",F6/F5-1) | H6: =SUMPRODUCT((수출실적!$C$2:$C$359=$A6)*(수출실적!$L$2:$L$359=""))
A7: 2023-06 | B7: =SUMIFS(수출실적!$L$2:$L$359,수출실적!$C$2:$C$359,$A7,수출실적!$G$2:$G$359,"미국") | C7: =SUMIFS(수출실적!$L$2:$L$359,수출실적!$C$2:$C$359,$A7,수출실적!$G$2:$G$359,"멕시코") | D7: =SUMIFS(수출실적!$L$2:$L$359,수출실적!$C$2:$C$359,$A7,수출실적!$G$2:$G$359,"베트남") | E7: =SUMIFS(수출실적!$L$2:$L$359,수출실적!$C$2:$C$359,$A7,수출실적!$G$2:$G$359,"인도") | F7: =SUM(B7:E7) | G7: =IF(F6=0,"",F7/F6-1) | H7: =SUMPRODUCT((수출실적!$C$2:$C$359=$A7)*(수출실적!$L$2:$L$359=""))
A8: 2023-07 | B8: =SUMIFS(수출실적!$L$2:$L$359,수출실적!$C$2:$C$359,$A8,수출실적!$G$2:$G$359,"미국") | C8: =SUMIFS(수출실적!$L$2:$L$359,수출실적!$C$2:$C$359,$A8,수출실적!$G$2:$G$359,"멕시코") | D8: =SUMIFS(수출실적!$L$2:$L$359,수출실적!$C$2:$C$359,$A8,수출실적!$G$2:$G$359,"베트남") | E8: =SUMIFS(수출실적!$L$2:$L$359,수출실적!$C$2:$C$359,$A8,수출실적!$G$2:$G$359,"인도") | F8: =SUM(B8:E8) | G8: =IF(F7=0,"",F8/F7-1) | H8: =SUMPRODUCT((수출실적!$C$2:$C$359=$A8)*(수출실적!$L$2:$L$359=""))
A9: 2023-08 | B9: =SUMIFS(수출실적!$L$2:$L$359,수출실적!$C$2:$C$359,$A9,수출실적!$G$2:$G$359,"미국") | C9: =SUMIFS(수출실적!$L$2:$L$359,수출실적!$C$2:$C$359,$A9,수출실적!$G$2:$G$359,"멕시코") | D9: =SUMIFS(수출실적!$L$2:$L$359,수출실적!$C$2:$C$359,$A9,수출실적!$G$2:$G$359,"베트남") | E9: =SUMIFS(수출실적!$L$2:$L$359,수출실적!$C$2:$C$359,$A9,수출실적!$G$2:$G$359,"인도") | F9: =SUM(B9:E9) | G9: =IF(F8=0,"",F9/F8-1) | H9: =SUMPRODUCT((수출실적!$C$2:$C$359=$A9)*(수출실적!$L$2:$L$359=""))
A10: 2023-09 | B10: =SUMIFS(수출실적!$L$2:$L$359,수출실적!$C$2:$C$359,$A10,수출실적!$G$2:$G$359,"미국") | C10: =SUMIFS(수출실적!$L$2:$L$359,수출실적!$C$2:$C$359,$A10,수출실적!$G$2:$G$359,"멕시코") | D10: =SUMIFS(수출실적!$L$2:$L$359,수출실적!$C$2:$C$359,$A10,수출실적!$G$2:$G$359,"베트남") | E10: =SUMIFS(수출실적!$L$2:$L$359,수출실적!$C$2:$C$359,$A10,수출실적!$G$2:$G$359,"인도") | F10: =SUM(B10:E10) | G10: =IF(F9=0,"",F10/F9-1) | H10: =SUMPRODUCT((수출실적!$C$2:$C$359=$A10)*(수출실적!$L$2:$L$359=""))
A11: 2023-10 | B11: =SUMIFS(수출실적!$L$2:$L$359,수출실적!$C$2:$C$359,$A11,수출실적!$G$2:$G$359,"미국") | C11: =SUMIFS(수출실적!$L$2:$L$359,수출실적!$C$2:$C$359,$A11,수출실적!$G$2:$G$359,"멕시코") | D11: =SUMIFS(수출실적!$L$2:$L$359,수출실적!$C$2:$C$359,$A11,수출실적!$G$2:$G$359,"베트남") | E11: =SUMIFS(수출실적!$L$2:$L$359,수출실적!$C$2:$C$359,$A11,수출실적!$G$2:$G$359,"인도") | F11: =SUM(B11:E11) | G11: =IF(F10=0,"",F11/F10-1) | H11: =SUMPRODUCT((수출실적!$C$2:$C$359=$A11)*(수출실적!$L$2:$L$359=""))
A12: 2023-11 | B12: =SUMIFS(수출실적!$L$2:$L$359,수출실적!$C$2:$C$359,$A12,수출실적!$G$2:$G$359,"미국") | C12: =SUMIFS(수출실적!$L$2:$L$359,수출실적!$C$2:$C$359,$A12,수출실적!$G$2:$G$359,"멕시코") | D12: =SUMIFS(수출실적!$L$2:$L$359,수출실적!$C$2:$C$359,$A12,수출실적!$G$2:$G$359,"베트남") | E12: =SUMIFS(수출실적!$L$2:$L$359,수출실적!$C$2:$C$359,$A12,수출실적!$G$2:$G$359,"인도") | F12: =SUM(B12:E12) | G12: =IF(F11=0,"",F12/F11-1) | H12: =SUMPRODUCT((수출실적!$C$2:$C$359=$A12)*(수출실적!$L$2:$L$359=""))
A13: 2023-12 | B13: =SUMIFS(수출실적!$L$2:$L$359,수출실적!$C$2:$C$359,$A13,수출실적!$G$2:$G$359,"미국") | C13: =SUMIFS(수출실적!$L$2:$L$359,수출실적!$C$2:$C$359,$A13,수출실적!$G$2:$G$359,"멕시코") | D13: =SUMIFS(수출실적!$L$2:$L$359,수출실적!$C$2:$C$359,$A13,수출실적!$G$2:$G$359,"베트남") | E13: =SUMIFS(수출실적!$L$2:$L$359,수출실적!$C$2:$C$359,$A13,수출실적!$G$2:$G$359,"인도") | F13: =SUM(B13:E13) | G13: =IF(F12=0,"",F13/F12-1) | H13: =SUMPRODUCT((수출실적!$C$2:$C$359=$A13)*(수출실적!$L$2:$L$359=""))
A14: 2024-01 | B14: =SUMIFS(수출실적!$L$2:$L$359,수출실적!$C$2:$C$359,$A14,수출실적!$G$2:$G$359,"미국") | C14: =SUMIFS(수출실적!$L$2:$L$359,수출실적!$C$2:$C$359,$A14,수출실적!$G$2:$G$359,"멕시코") | D14: =SUMIFS(수출실적!$L$2:$L$359,수출실적!$C$2:$C$359,$A14,수출실적!$G$2:$G$359,"베트남") | E14: =SUMIFS(수출실적!$L$2:$L$359,수출실적!$C$2:$C$359,$A14,수출실적!$G$2:$G$359,"인도") | F14: =SUM(B14:E14) | G14: =IF(F13=0,"",F14/F13-1) | H14: =SUMPRODUCT((수출실적!$C$2:$C$359=$A14)*(수출실적!$L$2:$L$359=""))
... A37: 2025-12 | B37: =SUMIFS(수출실적!$L$2:$L$359,수출실적!$C$2:$C$359,$A37,수출실적!$G$2:$G$359,"미국") | C37: =SUMIFS(수출실적!$L$2:$L$359,수출실적!$C$2:$C$359,$A37,수출실적!$G$2:$G$359,"멕시코") | D37: =SUMIFS(수출실적!$L$2:$L$359,수출실적!$C$2:$C$359,$A37,수출실적!$G$2:$G$359,"베트남") | E37: =SUMIFS(수출실적!$L$2:$L$359,수출실적!$C$2:$C$359,$A37,수출실적!$G$2:$G$359,"인도") | F37: =SUM(B37:E37) | G37: =IF(F36=0,"",F37/F36-1) | H37: =SUMPRODUCT((수출실적!$C$2:$C$359=$A37)*(수출실적!$L$2:$L$359=""))
A39: 금액은 수출실적 시트 합계(SUMIFS). 금액 빈칸은 0으로 더해지므로 '금액 빈칸 행수'가 0이 아닌 달은 합계를 그대로 쓰지 말 것.
A40: 회사 자체 수출 흐름 참고용. 대시보드 안정성(목적국 수입금액 CV·급감)은 공개 무역통계로 계산하며 이 표와 다름.

Sheet 결측목록
A1: 새벽반도체 — 의도적으로 넣은 결측·예외 위치 (검증 로직 테스트용)
A2: 처리 원칙: 빈칸은 '자료 부족'으로 표시하고 0·임의 값으로 채우지 않음. 실제 0(취소 건)과 빈칸을 구분. 행 자체가 없는 달은 '자료 없음'.
A4: 구분 | B4: 시트 | C4: 셀/행 | D4: 식별자 | E4: 비어 있는 항목 | F4: 대시보드 영향 | G4: 권장 처리
A5: 기업 정보 | B5: 기업정보 | C5: B8 | D5: company | E5: 금액 통화 | F5: 결제통화 불명 → 참고환율 통화 선택 불가 | G5: '통화 미확인' 표시, 환율 카드 자료 부족
A6: 제품 HS | B6: 제품정보 | C6: D4:E4 | D6: P-SB-003 | E6: 입력HSK, HS코드 | F6: 규제 통제번호 후보 조회 불가, 관세 참고치 조회 불가 | G6: 'HS 미확인'으로 분리, 이 제품 금액은 HS별 집계에서 제외하고 건수 표시
A7: 거래처 | B7: 거래처 | C7: D4 | D7: C-SB-03 | E7: 주소 | F7: CSL 검색 시 주소 대조 불가(명칭만 검색) | G7: 명칭 검색만 수행, '주소 미기재' 표시
A8: 거래처 | B8: 거래처 | C8: B5 | D8: C-SB-04 | E8: 법인명 (별칭만 있음) | F8: CSL 명칭 검색 불가 | G8: '검색 불가 — 법인명 없음' 표시, '일치 없음'으로 처리하지 않음
A9: 수출실적 | B9: 수출실적 | C9: E3 | D9: R-SB-0002 | E9: 제품ID | F9: 제품·HS 연결 불가 → HS별 집계 제외 | G9: 행은 보존, 해당 계산만 제외하고 제외 건수 표시
A10: 수출실적 | B10: 수출실적 | C10: K9 | D10: R-SB-0008 | E10: 순중량(kg) | F10: kg당 단가 계산에서 제외 | G10: 행은 보존, 해당 계산만 제외하고 제외 건수 표시
A11: 수출실적 | B11: 수출실적 | C11: L14 | D11: R-SB-0012 | E11: 금액 | F11: 월별 합계·단가 계산에서 제외 (0으로 더하지 않음) | G11: 행은 보존, 해당 계산만 제외하고 제외 건수 표시
A12: 수출실적 | B12: 수출실적 | C12: L16 | D12: R-SB-0014 | E12: 금액 | F12: 월별 합계·단가 계산에서 제외 (0으로 더하지 않음) | G12: 행은 보존, 해당 계산만 제외하고 제외 건수 표시
A13: 수출실적 | B13: 수출실적 | C13: K20 | D13: R-SB-0018 | E13: 순중량(kg) | F13: kg당 단가 계산에서 제외 | G13: 행은 보존, 해당 계산만 제외하고 제외 건수 표시
A14: 수출실적 | B14: 수출실적 | C14: K21 | D14: R-SB-0019 | E14: 순중량(kg) | F14: kg당 단가 계산에서 제외 | G14: 행은 보존, 해당 계산만 제외하고 제외 건수 표시
A15: 수출실적 | B15: 수출실적 | C15: L24 | D15: R-SB-0022 | E15: 금액 | F15: 월별 합계·단가 계산에서 제외 (0으로 더하지 않음) | G15: 행은 보존, 해당 계산만 제외하고 제외 건수 표시
... A73: 물류 | B73: 물류 | C73: K334 | D73: L-SB-0333 | E73: 운임(USD) | F73: 운송비 비중 계산에서 제외 | G73: 행은 보존, 해당 계산만 제외하고 제외 건수 표시
